<?xml version="1.0" encoding="utf-8"?>
<!-- =================================================================================== -->
<!-- |    This document was autogenerated by xacro from urdf/sailboat_base.urdf.xacro  | -->
<!-- |    EDITING THIS FILE BY HAND IS NOT RECOMMENDED                                 | -->
<!-- =================================================================================== -->
<robot name="sailboat">
  <!-- HULL DESCRIPTION -->
  <link name="base_link">
    <visual>
      <origin rpy="0 0 0" xyz="0 0 0.0"/>
      <geometry>
        <mesh filename="package://sailboat_description/mesh/pt90.stl"/>
      </geometry>
      <material name="blue"/>
    </visual>
    <collision>
      <origin rpy="0 0 0" xyz="0 0 0.0"/>
      <geometry>
        <mesh filename="package://sailboat_description/mesh/pt90.stl"/>
      </geometry>
    </collision>
    <inertial>
      <origin rpy="0 0 0" xyz="0 0 0.0"/>
      <mass value="50.0"/>
      <inertia ixx="0.3" ixy="0.0" ixz="0.0" iyy="3.5" iyz="0.0" izz="3.6"/>
    </inertial>
  </link>
  <!-- RUDDER DESCRIPTION -->
  <link name="rudder">
    <inertial>
      <mass value="1.0"/>
      <inertia ixx="0.0" ixy="0.0" ixz="0.0" iyy="0.0" iyz="0.0" izz="0.0"/>
    </inertial>
    <collision name="collision">
      <geometry>
        <mesh filename="package://sailboat_description/mesh/rudder.stl"/>
      </geometry>
      <origin rpy="0 0 0" xyz="0.0 0 0"/>
    </collision>
    <visual name="visual">
      <geometry>
        <mesh filename="package://sailboat_description/mesh/rudder.stl"/>
      </geometry>
      <origin rpy="0 0 0" xyz="0.0 0 0"/>
    </visual>
  </link>
  <joint name="rudder_joint" type="revolute">
    <parent link="base_link"/>
    <child link="rudder"/>
    <origin rpy="0 0 0" xyz="-0.4 0 0"/>
    <dynamics damping="1.0"/>
    <axis xyz="0 0 1"/>
    <limit effort="50" lower="-1.0471975512" upper="1.0471975512" velocity="5"/>
  </joint>
  <!-- SAIL DESCRIPTION -->
  <link name="sail">
    <inertial>
      <mass value="2.0"/>
      <inertia ixx="0.0" ixy="0.0" ixz="0.0" iyy="0.0" iyz="0.0" izz="0.0"/>
    </inertial>
    <collision name="collision">
      <geometry>
        <mesh filename="package://sailboat_description/mesh/sail.dae"/>
      </geometry>
      <origin rpy="0 0 0" xyz="0.0 0 0.0"/>
    </collision>
    <visual name="visual">
      <geometry>
        <mesh filename="package://sailboat_description/mesh/sail.dae"/>
      </geometry>
      <origin rpy="0 0 0" xyz="0.0 0 0.0"/>
    </visual>
  </link>
  <joint name="sail_joint" type="revolute">
    <parent link="base_link"/>
    <child link="sail"/>
    <origin rpy="0 0 0" xyz="0.25 0 0"/>
    <dynamics damping="1.0"/>
    <axis xyz="0 0 1"/>
    <limit effort="30" lower="-1.57079632679" upper="1.57079632679" velocity="5"/>
  </joint>
  <!-- KEEL DESCRIPTION -->
  <link name="keel">
    <inertial>
      <mass value="10.0" xyz="0 0 0"/>
      <inertia ixx="0.05" ixy="0.0" ixz="0.0" iyy="0.05" iyz="0.0" izz="0.005"/>
    </inertial>
    <collision name="collision">
      <geometry>
        <mesh filename="package://sailboat_description/mesh/keel.stl"/>
      </geometry>
      <origin rpy="0 0 0" xyz="0 0 0"/>
    </collision>
    <visual name="visual">
      <geometry>
        <mesh filename="package://sailboat_description/mesh/keel.stl"/>
      </geometry>
      <origin rpy="0 0 0" xyz="0 0 0"/>
    </visual>
  </link>
  <joint name="keel_joint" type="revolute">
    <parent link="base_link"/>
    <child link="keel"/>
    <origin rpy="0 0 0" xyz="0 0 0"/>
    <axis xyz="0 0 1"/>
    <limit effort="50" lower="0" upper="0" velocity="0"/>
  </joint>
  <gazebo>
    <plugin filename="libgazebo_ros_control.so" name="gazebo_ros_control">
      <robotNamespace>/sailboat</robotNamespace>
    </plugin>
    <plugin filename="libLiftDragPlugin.so" name="lifting_surface1">
      <!-- taken from the lift curve figure -->
      <!-- alpha_0 is 5 degrees -->
      <a0>0.08727</a0>
      <!-- alpha_stall is 19.3 degrees -->
      <alpha_stall>0.3368</alpha_stall>
      <!-- slope of the lift curve to the left of the stall angle -->
      <cla>5.418</cla>
      <!-- slope of the lift curve to the right of the stall angle -->
      <cla_stall>-2.1419</cla_stall>
      <!-- below are just random values in this example -->
      <cda>0.0</cda>
      <cda_stall>0.0</cda_stall>
      <cma>0.0</cma>
      <cma_stall>0.0</cma_stall>
      <area>3</area>
      <fluid_density>1.2041</fluid_density>
      <forward>-1 0 0</forward>
      <upward>0 -1 0</upward>
      <cp>0 0 1</cp>
      <link_name>sail</link_name>
      <radial_symmetry>false</radial_symmetry>
    </plugin>
    <plugin filename="libLiftDragPlugin.so" name="lifting_surface2">
      <!-- taken from the lift curve figure -->
      <!-- alpha_0 is 5 degrees -->
      <a0>0.08727</a0>
      <!-- alpha_stall is 19.3 degrees -->
      <alpha_stall>0.3368</alpha_stall>
      <!-- slope of the lift curve to the left of the stall angle -->
      <cla>5.418</cla>
      <!-- slope of the lift curve to the right of the stall angle -->
      <cla_stall>-2.1419</cla_stall>
      <!-- below are just random values in this example -->
      <cda>0.0</cda>
      <cda_stall>0.0</cda_stall>
      <cma>0.0</cma>
      <cma_stall>0.0</cma_stall>
      <area>3</area>
      <fluid_density>1.2041</fluid_density>
      <forward>-1 0 0</forward>
      <upward>0 -1 0</upward>
      <cp>0 0 1</cp>
      <link_name>rudder</link_name>
      <radial_symmetry>false</radial_symmetry>
    </plugin>
  </gazebo>
  <transmission name="sail_trans">
    <type>transmission_interface/SimpleTransmission</type>
    <actuator name="sail_act">
      <mechanicalReduction>1</mechanicalReduction>
    </actuator>
    <joint name="sail_joint">
      <hardwareInterface>hardware_interface/PositionJointInterface</hardwareInterface>
    </joint>
  </transmission>
  <transmission name="rudder_trans">
    <type>transmission_interface/SimpleTransmission</type>
    <actuator name="rudder_act">
      <mechanicalReduction>1</mechanicalReduction>
    </actuator>
    <joint name="rudder_joint">
      <hardwareInterface>hardware_interface/PositionJointInterface</hardwareInterface>
    </joint>
  </transmission>
</robot>
